<?xml version='1.0'?>

<robot name="my_robot" xmlns:xacro="http://www.ros.org/wiki/xacro">
  <xacro:include filename="$(find chaser_robot)/urdf/chaser_robot.gazebo" />
  <xacro:include filename="$(find chaser_robot)/urdf/materials.xacro" />
  <xacro:include filename="$(find chaser_robot)/urdf/imu.gazebo" />
  <link name="robot_footprint"></link>

  <joint name="robot_footprint_joint" type="fixed">
    <origin xyz="0 0 0" rpy="0 0 0" />
    <parent link="robot_footprint"/>
    <child link="chassis" />
  </joint>

  <link name='chassis'>
    <pose>0 0 0.1 0 0 0</pose>

    <inertial>
      <mass value="15.0"/>
      <origin xyz="0.0 0 0" rpy=" 0 0 0"/>
      <inertia
          ixx="0.1" ixy="0" ixz="0"
          iyy="0.1" iyz="0"
          izz="0.1"
      />
    </inertial>

    <collision name='collision'>
      <origin xyz="0 0 0" rpy=" 0 0 0"/> 
      <geometry>
        <box size=".4 .2 .1"/>
      </geometry>
    </collision>

    <visual name='chassis_visual'>
      <origin xyz="0 0 0" rpy=" 0 0 0"/>
      <geometry>
        <box size=".4 .2 .1"/>
      </geometry>
      <material name="black"/>
    </visual>
 
    <!--collision name='front_caster_collision'>
      <origin xyz="0.15 0 -0.05" rpy=" 0 0 0"/>
      <geometry>
        <sphere radius="0.0499"/>
      </geometry>
    </collision>
    <visual name='front_caster_visual'>
      <origin xyz="0.15 0 -0.05" rpy=" 0 0 0"/>
      <geometry>
        <sphere radius="0.05"/>
      </geometry>
    </visual>

    <inertial>
      <origin xyz="0.0 0.0 0.0" rpy="0.0 1.5707 1.5707"/>
      <mass value="5.0"/>
      <inertia ixx="0.1" ixy="0.0" ixz="0.0" iyy="0.1" iyz="0.0" izz="0.1"/>
    </inertial-->


  </link>


<link name="F_left_wheel">
    <collision name='F_left_wheel_collision'>
      <origin xyz="0 0 0" rpy=" 0 1.5705 1.5705"/>
      <geometry>
        <cylinder radius="0.08" length="0.05"/>
      </geometry>
    </collision>

    <visual name='F_left_wheel_visual'>
      <origin xyz="0 0 0" rpy=" 0 1.5705 1.5705"/>
      <geometry>
        <cylinder radius="0.08" length="0.05"/>
      </geometry>
      <material name="blue"/>
    </visual>

    <inertial>
      <origin xyz="0.0 0.0 0.0" rpy="0.0 1.5707 1.5707"/>
      <mass value="5.0"/>
      <inertia ixx="0.1" ixy="0.0" ixz="0.0" iyy="0.1" iyz="0.0" izz="0.1"/>
    </inertial>
  </link>

  <link name="F_right_wheel">
    
  
    <collision name='F_right_wheel_collision'>
      <origin xyz="0 0 0" rpy=" 0 1.5705 1.5705"/>
      <geometry>
        <cylinder radius="0.08" length="0.05"/>
      </geometry>
    </collision>

    <visual name='F_right_wheel_visual'>
      <origin xyz="0 0 0" rpy=" 0 1.5705 1.5705"/>
      <geometry>
        <cylinder radius="0.08" length="0.05"/>
      </geometry>
      <material name="blue"/>
    </visual>

    <inertial>
      <origin xyz="0.0 0.0 0.0" rpy="0.0 1.5707 1.5707"/>
      <mass value="5.0"/>
      <inertia ixx="0.1" ixy="0.0" ixz="0.0" iyy="0.1" iyz="0.0" izz="0.1"/>
    </inertial>
  </link>







  <link name="B_left_wheel">
    <collision name='B_left_wheel_collision'>
      <origin xyz="0 0 0" rpy=" 0 1.5705 1.5705"/>
      <geometry>
        <cylinder radius="0.08" length="0.05"/>
      </geometry>
    </collision>

    <visual name='B_left_wheel_visual'>
      <origin xyz="0 0 0" rpy=" 0 1.5705 1.5705"/>
      <geometry>
        <cylinder radius="0.08" length="0.05"/>
      </geometry>
      <material name="blue"/>
    </visual>

    <inertial>
      <origin xyz="0.0 0.0 0.0" rpy="0.0 1.5707 1.5707"/>
      <mass value="5.0"/>
      <inertia ixx="0.1" ixy="0.0" ixz="0.0" iyy="0.1" iyz="0.0" izz="0.1"/>
    </inertial>
  </link>

  <link name="B_right_wheel">
    
  
    <collision name='B_right_wheel_collision'>
      <origin xyz="0 0 0" rpy=" 0 1.5705 1.5705"/>
      <geometry>
        <cylinder radius="0.08" length="0.05"/>
      </geometry>
    </collision>

    <visual name='B_right_wheel_visual'>
      <origin xyz="0 0 0" rpy=" 0 1.5705 1.5705"/>
      <geometry>
        <cylinder radius="0.08" length="0.05"/>
      </geometry>
      <material name="blue"/>
    </visual>

    <inertial>
      <origin xyz="0.0 0.0 0.0" rpy="0.0 1.5707 1.5707"/>
      <mass value="5.0"/>
      <inertia ixx="0.1" ixy="0.0" ixz="0.0" iyy="0.1" iyz="0.0" izz="0.1"/>
    </inertial>
  </link>
   

<joint type="continuous" name="F_left_wheel_hinge">
    <origin xyz="0.13 0.15 0" rpy="0 0 0"/>
    <child link="F_left_wheel"/>
    <parent link="chassis"/>
    <axis xyz="0 1 0" rpy="0 0 0"/>
    <limit effort="10000" velocity="1000"/>
    <dynamics damping="1.0" friction="1.0"/>
  </joint>


  <joint type="continuous" name="F_right_wheel_hinge">
    <origin xyz="0.13 -0.15 0" rpy="0 0 0"/>
    <child link="F_right_wheel"/>
    <parent link="chassis"/>
    <axis xyz="0 1 0" rpy="0 0 0"/>
    <limit effort="10000" velocity="1000"/>
    <dynamics damping="1.0" friction="1.0"/>
  </joint>




   
  <joint type="continuous" name="B_left_wheel_hinge">
    <origin xyz="-0.15 0.15 0" rpy="0 0 0"/>
    <child link="B_left_wheel"/>
    <parent link="chassis"/>
    <axis xyz="0 1 0" rpy="0 0 0"/>
    <limit effort="10000" velocity="1000"/>
    <dynamics damping="1.0" friction="1.0"/>
  </joint>


  <joint type="continuous" name="B_right_wheel_hinge">
    <origin xyz="-0.15 -0.15 0" rpy="0 0 0"/>
    <child link="B_right_wheel"/>
    <parent link="chassis"/>
    <axis xyz="0 1 0" rpy="0 0 0"/>
    <limit effort="10000" velocity="1000"/>
    <dynamics damping="1.0" friction="1.0"/>
  </joint>
  

  <link name="camera">
      <inertial>
        <origin xyz="0.0 0.0 0.0" rpy="0.0 0.0 0.0"/>
        <mass value="0.1"/>
        <inertia ixx="1e-6" ixy="0.0" ixz="0.0" iyy="1e-6" iyz="0.0" izz="1e-6"/>
      </inertial>
      <visual name="">
        <origin xyz="0.0 0.0 0.0" rpy="0.0 0.0 0.0"/>
        <geometry>
          <box size="0.05 0.05 0.05"/>
        </geometry>
        
      </visual>
      <collision>
        <origin xyz="0.0 0.0 0.0" rpy="0.0 0.0 0.0"/>
        <geometry>
          <box size="0.05 0.05 0.05"/>
        </geometry>
      </collision>
      <gazebo reference="camera">
          <material>Gazebo/Green</material>
      </gazebo>
  </link>

  <joint name="camera_joint" type="fixed">
    <origin xyz="0.2 0.0 0.0" rpy="0.0 0.0 0.0"/>
    <parent link="chassis"/>
    <child link="camera"/>
    <axis xyz="0.0 1 0.0"/>
  </joint>



  <link name="hokuyo">
      <inertial>
        <origin xyz="0.0 0.0 0.0" rpy="0.0 0.0 0.0"/>
        <mass value="0.1"/>
        <inertia ixx="1e-6" ixy="0.0" ixz="0.0" iyy="1e-6" iyz="0.0" izz="1e-6"/>
      </inertial>
      <visual name="hokuyo_visual">
        <origin xyz="0.0 0.0 0.0" rpy="0.0 0.0 0.0"/>
        <geometry>
          <mesh filename="package://chaser_robot/meshes/hokuyo.dae"/>
        </geometry>
        <material name="blue">
          <color rgba="100.0 0.0 0.0 1.0"/>
        </material>
      </visual>
      <collision>
        <origin xyz="0.0 0.0 0.0" rpy="0.0 0.0 0.0"/>
        <geometry>
          <box size="0.1 0.1 0.1"/>
        </geometry>
      </collision>
    </link>

  <joint name="hokuyo_joint" type="fixed">
    <origin xyz="0.15 0.0 0.07" rpy="0.0 0.0 0.0"/>
    <parent link="chassis"/>
    <child link="hokuyo"/>
    <axis xyz="0.0 1 0.0"/>
  </joint>

  <link name="imu_sensor">
      <inertial>
        <origin xyz="0.0 0.0 0.0" rpy="0.0 0.0 0.0"/>
        <mass value="0.1"/>
        <inertia ixx="1e-6" ixy="0.0" ixz="0.0" iyy="1e-6" iyz="0.0" izz="1e-6"/>
      </inertial>
      <visual name="imu_sensor_visual">
        <origin xyz="0.0 0.0 0.0" rpy="0.0 0.0 0.0"/>
        <geometry>
          <box size="0.05 0.05 0.05"/>
        </geometry>
        
      </visual>
      <collision>
        <origin xyz="0.0 0.0 0.0" rpy="0.0 0.0 0.0"/>
        <geometry>
          <box size="0.05 0.05 0.05"/>
        </geometry>
      </collision>
      <gazebo reference="imu_sensor">
          <material>Gazebo/Green</material>
      </gazebo>
  </link>

  <joint name="imu_sensor_joint" type="fixed">
    <origin xyz="0.0 0.0 0.05" rpy="0.0 0.0 0.0"/>
    <parent link="chassis"/>
    <child link="imu_sensor"/>
    <axis xyz="0.0 1 0.0"/>
  </joint>



</robot>

